Workbook

Sheet Search Term
C1: Rank | E1: Share | G1: Clicks | I1: Impressions | K1: CTR | M1: CPC | O1: Spend | Q1: Orders | S1: CR | U1: Sales | W1: ACOS | Y1: ROAS
A2: Customer Search Term | B2: Orders Diff | C2: march | D2: april | E2: march | F2: april | G2: march | H2: april | I2: march | J2: april | K2: march | L2: april | M2: march | N2: april | O2: march | P2: april | Q2: march | R2: april | S2: march | T2: april | U2: march | V2: april | W2: march | X2: april | Y2: march | Z2: april | AA2: Order
A3: ergoyou height adjustable table desk | B3: =R3-Q3 -> 7 | C3: 1 | D3: 1 | E3: 0.7167 | F3: 0.9352 | G3: 225 | H3: 239 | I3: 82822 | J3: 78901 | K3: 0.0027166695 | L3: 0.0030291124 | M3: 30.880178 | N3: 40.547364 | O3: 6948.04 | P3: 9690.82 | Q3: 8 | R3: 15 | S3: 0.035555556 | T3: 0.062761506 | U3: 174788.11 | V3: 301906.77 | W3: 0.039751216 | X3: 0.032098717 | Y3: 25.156463 | Z3: 31.153893 | AA3: 23
A4: height adjustable table | B4: =R4-Q4 -> -5 | C4: 3.5909091 | D4: 3 | E4: 0.089009091 | F4: 0.088259091 | G4: 1899 | H4: 1871 | I4: 376351 | J4: 382541 | K4: 0.0050458216 | L4: 0.004890979 | M4: 32.633017 | N4: 33.552181 | O4: 61970.1 | P4: 62776.13 | Q4: 13 | R4: 8 | S4: 0.0068457083 | T4: 0.0042757883 | U4: 277203.39 | V4: 161271.17 | W4: 0.22355463 | X4: 0.38925823 | Y4: 4.4731796 | Z4: 2.5689887 | AA4: 21
A5: standing desk | B5: =R5-Q5 -> -2 | C5: 2.5714286 | D5: 2 | E5: 0.088228571 | F5: 0.1029625 | G5: 896 | H5: 1002 | I5: 75450 | J5: 76373 | K5: 0.011875414 | L5: 0.01311982 | M5: 35.397991 | N5: 39.378463 | O5: 31716.6 | P5: 39457.22 | Q5: 10 | R5: 8 | S5: 0.011160714 | T5: 0.0079840319 | U5: 197033.9 | V5: 181779.65 | W5: 0.16097027 | X5: 0.21706071 | Y5: 6.2123273 | Z5: 4.607006 | AA5: 18
A6: ergo you height adjustable table | B6: =R6-Q6 -> 2 | C6: 1 | D6: 1 | E6: 0.7718 | F6: 0.9792 | G6: 137 | H6: 188 | I6: 42720 | J6: 57695 | K6: 0.0032069288 | L6: 0.0032585146 | M6: 42.78854 | N6: 48.150638 | O6: 5862.03 | P6: 9052.32 | Q6: 6 | R6: 8 | S6: 0.04379562 | T6: 0.042553191 | U6: 124490.67 | V6: 182456.77 | W6: 0.047088107 | X6: 0.049613506 | Y6: 21.236785 | Z6: 20.155802 | AA6: 14
A7: electric height adjustable table | B7: =R7-Q7 -> -7 | C7: 2 | D7: 1.8888889 | E7: 0.3606 | F7: 0.46673333 | G7: 240 | H7: 167 | I7: 146492 | J7: 111057 | K7: 0.0016383147 | L7: 0.0015037323 | M7: 51.771583 | N7: 60.21994 | O7: 12425.18 | P7: 10056.73 | Q7: 8 | R7: 1 | S7: 0.033333333 | T7: 0.005988024 | U7: 172988.98 | V7: 26186.44 | W7: 0.071826425 | X7: 0.38404342 | Y7: 13.922453 | Z7: 2.6038722 | AA7: 9
A8: height adjustable desk | B8: =R8-Q8 -> 5 | C8: 4.2857143 | D8: 3.1818182 | E8: 0.075271429 | F8: 0.094468182 | G8: 474 | H8: 562 | I8: 46858 | J8: 93202 | K8: 0.010115669 | L8: 0.0060299135 | M8: 31.184135 | N8: 34.807064 | O8: 14781.28 | P8: 19561.57 | Q8: 2 | R8: 7 | S8: 0.0042194093 | T8: 0.012455516 | U8: 38983.05 | V8: 142710.99 | W8: 0.37917197 | X8: 0.13707122 | Y8: 2.6373257 | Z8: 7.2954773 | AA8: 9
A9: sit stand desk | B9: =R9-Q9 -> -3 | C9: 4 | D9: 4 | E9: 0.0532 | F9: 0.058433333 | G9: 387 | H9: 357 | I9: 123296 | J9: 160508 | K9: 0.003138788 | L9: 0.0022241882 | M9: 43.605917 | N9: 50.885602 | O9: 16875.49 | P9: 18166.16 | Q9: 6 | R9: 3 | S9: 0.015503876 | T9: 0.0084033613 | U9: 106864.41 | V9: 63220.34 | W9: 0.15791497 | X9: 0.28734676 | Y9: 6.3325219 | Z9: 3.4801158 | AA9: 9
A10: b08lgjgzj1 | B10: =R10-Q10 -> 7 | C10: 2 | D10: 2 | E10: 0.1384 | F10: 0.3433 | G10: 119 | H10: 408 | I10: 10353 | J10: 23914 | K10: 0.011494253 | L10: 0.017061136 | M10: 28.933613 | N10: 42.711495 | O10: 3443.1 | P10: 17426.29 | Q10: 0 | R10: 7 | S10: 0 | T10: 0.017156863 | U10: 0 | V10: 98045.78 | W10: 0 | X10: 0.17773626 | Y10: 0 | Z10: 5.626314 | AA10: 7
A11: adjustable table | B11: =R11-Q11 -> -3 | C11: 16 | D11: 9.8888889 | E11: 0.20725556 | F11: 0.24098889 | G11: 867 | H11: 653 | I11: 29737 | J11: 18291 | K11: 0.029155597 | L11: 0.035700618 | M11: 10.977612 | N11: 9.9665697 | O11: 9517.59 | P11: 6508.17 | Q11: 4 | R11: 1 | S11: 0.0046136101 | T11: 0.0015313936 | U11: 72118.64 | V11: 25338.98 | W11: 0.13197129 | X11: 0.2568442 | Y11: 7.5774056 | Z11: 3.8934109 | AA11: 5
A12: b0cnxslf8j | B12: =R12-Q12 -> -3 | C12: 1 | D12: 1 | E12: 0.9794 | F12: 0.9909 | G12: 168 | H12: 103 | I12: 37374 | J12: 31738 | K12: 0.0044951035 | L12: 0.0032453211 | M12: 41.000714 | N12: 75.62 | O12: 6888.12 | P12: 7788.86 | Q12: 4 | R12: 1 | S12: 0.023809524 | T12: 0.0097087379 | U12: 74150.86 | V12: 12541.52 | W12: 0.092893326 | X12: 0.62104593 | Y12: 10.765036 | Z12: 1.6101869 | AA12: 5
A13: ergoyou | B13: =R13-Q13 -> -5 | C13: 1 | D13: 1.2 | E13: 0.9035 | F13: 0.79886 | G13: 59 | H13: 38 | I13: 1637 | J13: 944 | K13: 0.036041539 | L13: 0.040254237 | M13: 14.088983 | N13: 11.913684 | O13: 831.25 | P13: 452.72 | Q13: 5 | R13: 0 | S13: 0.084745763 | T13: 0 | U13: 64829.66 | V13: 0 | W13: 0.012822063 | X13: 0 | Y13: 77.990568 | Z13: 0 | AA13: 5
A14: sit stand desk electric | B14: =R14-Q14 -> -5 | C14: 2.2 | D14: 1.6666667 | E14: 0.3251 | F14: 0.302 | G14: 178 | H14: 112 | I14: 65959 | J14: 25303 | K14: 0.0026986461 | L14: 0.0044263526 | M14: 51.345337 | N14: 53.620357 | O14: 9139.47 | P14: 6005.48 | Q14: 5 | R14: 0 | S14: 0.028089888 | T14: 0 | U14: 98389.83 | V14: 0 | W14: 0.092890393 | X14: 0 | Y14: 10.765376 | Z14: 0 | AA14: 5
... A113: Grand Total | B113: =R113-Q113 -> -12 | C113: 9.2603661 | D113: 11.132872 | E113: 0.3995709 | F113: 0.36391616 | G113: 13981 | H113: 14792 | I113: 1790080 | J113: 1776198 | K113: 0.0078102655 | L113: 0.0083279004 | M113: 26.885124 | N113: 28.301501 | O113: 375880.92 | P113: 418635.81 | Q113: 139 | R113: 127 | S113: 0.0099420642 | T113: 0.008585722 | U113: 2506936.4 | V113: 2198656.7 | W113: 0.14993636 | X113: 0.19040527 | Y113: 6.6694962 | Z113: 5.2519555 | AA113: 266

Sheet Monthly
A1: Month | B1: Amt Spent | C1: Imp | D1: CTR | E1: Clicks | F1: CPC | G1: Paid Orders | H1: CR | I1: Paid Revenue | J1: Paid ACOS | K1: Paid AOV | L1: ROAS | M1: Total Orders | N1: Total Sale | O1: Total AOV | P1: TACOS | Q1: ROI | R1: Organic Orders | S1: Organic Sale | T1: Organic AOV | U1: Sessions | V1: Session % | W1: Buy Box % | X1: Organic to Paid Orders | Y1: Organic Orders Contribution | Z1: Organic Sales Contribution | AA1: B2b Unit | AB1: B2b Unit
A2: Nov | B2: =SUMIFS('Campaign - Dump'!$Q:$Q,'Campaign - Dump'!$A:$A,Monthly!$A2) -> 163075.05 | C2: =SUMIFS('Campaign - Dump'!$N:$N,'Campaign - Dump'!$A:$A,Monthly!$A2) -> 4056219 | D2: =IFERROR(E2/C2,0) -> 0.0031948472 | E2: =SUMIFS('Campaign - Dump'!$O:$O,'Campaign - Dump'!$A:$A,Monthly!$A2) -> 12959 | F2: =IFERROR(B2/E2,0) -> 12.583922 | G2: =SUMIFS('Campaign - Dump'!$T:$T,'Campaign - Dump'!$A:$A,Monthly!$A2) -> 49 | H2: =IFERROR(G2/E2,0) -> 0.003781156 | I2: =SUMIFS('Campaign - Dump'!$U:$U,'Campaign - Dump'!$A:$A,Monthly!$A2) -> 843788.92 | J2: =IFERROR(B2/I2,0) -> 0.19326522 | K2: =IFERROR(I2/G2,0) -> 17220.182 | L2: =IFERROR(I2/B2,0) -> 5.1742368 | M2: =SUMIFS('Business - Dump'!$W:$W,'Business - Dump'!$A:$A,Monthly!$A2) -> 107 | N2: =SUMIFS('Business - Dump'!$U:$U,'Business - Dump'!$A:$A,Monthly!$A2)/1.18 -> 1838959.3 | O2: =IFERROR(N2/M2,0) -> 17186.536 | P2: =IFERROR(B2/N2,0) -> 0.0886779 | Q2: =IFERROR(N2/B2,0) -> 11.276767 | R2: =IFERROR(M2-G2,0) -> 58 | S2: =IFERROR(N2-I2,0) -> 995170.4 | T2: =IFERROR(S2/R2,0) -> 17158.11 | U2: =SUMIFS('Business - Dump'!$G:$G,'Business - Dump'!$A:$A,Monthly!$A2) -> 24301 | V2: =IFERROR(M2/U2,0) -> 0.004403111 | W2: =AVERAGEIFS('Business - Dump'!$O:$O,'Business - Dump'!$A:$A,Monthly!$A2) -> 0.83806087 | X2: =R2/G2 -> 1.1836735 | Y2: =IFERROR(R2/M2,0) -> 0.54205607 | Z2: =IFERROR(S2/N2,0) -> 0.54115955 | AA2: =SUMIFS('Business - Dump'!$R:$R,'Business - Dump'!$A:$A,Monthly!$A2) -> 8 | AB2: =SUMIFS('Business - Dump'!$V:$V,'Business - Dump'!$A:$A,Monthly!$A2) -> 195598
A3: Dec | B3: =SUMIFS('Campaign - Dump'!$Q:$Q,'Campaign - Dump'!$A:$A,Monthly!$A3) -> 260856.05 | C3: =SUMIFS('Campaign - Dump'!$N:$N,'Campaign - Dump'!$A:$A,Monthly!$A3) -> 4473747 | D3: =IFERROR(E3/C3,0) -> 0.0038187229 | E3: =SUMIFS('Campaign - Dump'!$O:$O,'Campaign - Dump'!$A:$A,Monthly!$A3) -> 17084 | F3: =IFERROR(B3/E3,0) -> 15.269027 | G3: =SUMIFS('Campaign - Dump'!$T:$T,'Campaign - Dump'!$A:$A,Monthly!$A3) -> 140 | H3: =IFERROR(G3/E3,0) -> 0.0081948022 | I3: =SUMIFS('Campaign - Dump'!$U:$U,'Campaign - Dump'!$A:$A,Monthly!$A3) -> 2470927.7 | J3: =IFERROR(B3/I3,0) -> 0.10557009 | K3: =IFERROR(I3/G3,0) -> 17649.484 | L3: =IFERROR(I3/B3,0) -> 9.4723803 | M3: =SUMIFS('Business - Dump'!$W:$W,'Business - Dump'!$A:$A,Monthly!$A3) -> 214 | N3: =SUMIFS('Business - Dump'!$U:$U,'Business - Dump'!$A:$A,Monthly!$A3)/1.18 -> 3610176.3 | O3: =IFERROR(N3/M3,0) -> 16869.983 | P3: =IFERROR(B3/N3,0) -> 0.072255765 | Q3: =IFERROR(N3/B3,0) -> 13.839726 | R3: =IFERROR(M3-G3,0) -> 74 | S3: =IFERROR(N3-I3,0) -> 1139248.6 | T3: =IFERROR(S3/R3,0) -> 15395.251 | U3: =SUMIFS('Business - Dump'!$G:$G,'Business - Dump'!$A:$A,Monthly!$A3) -> 31525 | V3: =IFERROR(M3/U3,0) -> 0.0067882633 | W3: =AVERAGEIFS('Business - Dump'!$O:$O,'Business - Dump'!$A:$A,Monthly!$A3) -> 0.872525 | X3: =R3/G3 -> 0.52857143 | Y3: =IFERROR(R3/M3,0) -> 0.34579439 | Z3: =IFERROR(S3/N3,0) -> 0.31556591 | AA3: =SUMIFS('Business - Dump'!$R:$R,'Business - Dump'!$A:$A,Monthly!$A3) -> 18 | AB3: =SUMIFS('Business - Dump'!$V:$V,'Business - Dump'!$A:$A,Monthly!$A3) -> 396598
A4: Jan | B4: =SUMIFS('Campaign - Dump'!$Q:$Q,'Campaign - Dump'!$A:$A,Monthly!$A4) -> 269951.38 | C4: =SUMIFS('Campaign - Dump'!$N:$N,'Campaign - Dump'!$A:$A,Monthly!$A4) -> 3237665 | D4: =IFERROR(E4/C4,0) -> 0.0041446536 | E4: =SUMIFS('Campaign - Dump'!$O:$O,'Campaign - Dump'!$A:$A,Monthly!$A4) -> 13419 | F4: =IFERROR(B4/E4,0) -> 20.117101 | G4: =SUMIFS('Campaign - Dump'!$T:$T,'Campaign - Dump'!$A:$A,Monthly!$A4) -> 82 | H4: =IFERROR(G4/E4,0) -> 0.0061107385 | I4: =SUMIFS('Campaign - Dump'!$U:$U,'Campaign - Dump'!$A:$A,Monthly!$A4) -> 1526285 | J4: =IFERROR(B4/I4,0) -> 0.17686827 | K4: =IFERROR(I4/G4,0) -> 18613.231 | L4: =IFERROR(I4/B4,0) -> 5.6539255 | M4: =SUMIFS('Business - Dump'!$W:$W,'Business - Dump'!$A:$A,Monthly!$A4) -> 156 | N4: =SUMIFS('Business - Dump'!$U:$U,'Business - Dump'!$A:$A,Monthly!$A4)/1.18 -> 2496815.5 | O4: =IFERROR(N4/M4,0) -> 16005.228 | P4: =IFERROR(B4/N4,0) -> 0.10811827 | Q4: =IFERROR(N4/B4,0) -> 9.2491304 | R4: =IFERROR(M4-G4,0) -> 74 | S4: =IFERROR(N4-I4,0) -> 970530.53 | T4: =IFERROR(S4/R4,0) -> 13115.277 | U4: =SUMIFS('Business - Dump'!$G:$G,'Business - Dump'!$A:$A,Monthly!$A4) -> 26612 | V4: =IFERROR(M4/U4,0) -> 0.0058620171 | W4: =AVERAGEIFS('Business - Dump'!$O:$O,'Business - Dump'!$A:$A,Monthly!$A4) -> 0.8818 | X4: =R4/G4 -> 0.90243902 | Y4: =IFERROR(R4/M4,0) -> 0.47435897 | Z4: =IFERROR(S4/N4,0) -> 0.38870735 | AA4: =SUMIFS('Business - Dump'!$R:$R,'Business - Dump'!$A:$A,Monthly!$A4) -> 16 | AB4: =SUMIFS('Business - Dump'!$V:$V,'Business - Dump'!$A:$A,Monthly!$A4) -> 265894.4
A5: Feb | B5: =SUMIFS('Campaign - Dump'!$Q:$Q,'Campaign - Dump'!$A:$A,Monthly!$A5) -> 363205.24 | C5: =SUMIFS('Campaign - Dump'!$N:$N,'Campaign - Dump'!$A:$A,Monthly!$A5) -> 3415714 | D5: =IFERROR(E5/C5,0) -> 0.0046774993 | E5: =SUMIFS('Campaign - Dump'!$O:$O,'Campaign - Dump'!$A:$A,Monthly!$A5) -> 15977 | F5: =IFERROR(B5/E5,0) -> 22.733006 | G5: =SUMIFS('Campaign - Dump'!$T:$T,'Campaign - Dump'!$A:$A,Monthly!$A5) -> 123 | H5: =IFERROR(G5/E5,0) -> 0.0076985667 | I5: =SUMIFS('Campaign - Dump'!$U:$U,'Campaign - Dump'!$A:$A,Monthly!$A5) -> 2203105.7 | J5: =IFERROR(B5/I5,0) -> 0.16486056 | K5: =IFERROR(I5/G5,0) -> 17911.429 | L5: =IFERROR(I5/B5,0) -> 6.0657322 | M5: =SUMIFS('Business - Dump'!$W:$W,'Business - Dump'!$A:$A,Monthly!$A5) -> 228 | N5: =SUMIFS('Business - Dump'!$U:$U,'Business - Dump'!$A:$A,Monthly!$A5)/1.18 -> 3525611.6 | O5: =IFERROR(N5/M5,0) -> 15463.209 | P5: =IFERROR(B5/N5,0) -> 0.10301907 | Q5: =IFERROR(N5/B5,0) -> 9.7069404 | R5: =IFERROR(M5-G5,0) -> 105 | S5: =IFERROR(N5-I5,0) -> 1322505.9 | T5: =IFERROR(S5/R5,0) -> 12595.294 | U5: =SUMIFS('Business - Dump'!$G:$G,'Business - Dump'!$A:$A,Monthly!$A5) -> 31719 | V5: =IFERROR(M5/U5,0) -> 0.0071881207 | W5: =AVERAGEIFS('Business - Dump'!$O:$O,'Business - Dump'!$A:$A,Monthly!$A5) -> 0.88219459 | X5: =R5/G5 -> 0.85365854 | Y5: =IFERROR(R5/M5,0) -> 0.46052632 | Z5: =IFERROR(S5/N5,0) -> 0.37511389 | AA5: =SUMIFS('Business - Dump'!$R:$R,'Business - Dump'!$A:$A,Monthly!$A5) -> 17 | AB5: =SUMIFS('Business - Dump'!$V:$V,'Business - Dump'!$A:$A,Monthly!$A5) -> 369473.29
A6: Mar | B6: =SUMIFS('Campaign - Dump'!$Q:$Q,'Campaign - Dump'!$A:$A,Monthly!$A6) -> 554591.97 | C6: =SUMIFS('Campaign - Dump'!$N:$N,'Campaign - Dump'!$A:$A,Monthly!$A6) -> 5184404 | D6: =IFERROR(E6/C6,0) -> 0.0047162605 | E6: =SUMIFS('Campaign - Dump'!$O:$O,'Campaign - Dump'!$A:$A,Monthly!$A6) -> 24451 | F6: =IFERROR(B6/E6,0) -> 22.68177 | G6: =SUMIFS('Campaign - Dump'!$T:$T,'Campaign - Dump'!$A:$A,Monthly!$A6) -> 196 | H6: =IFERROR(G6/E6,0) -> 0.0080160321 | I6: =SUMIFS('Campaign - Dump'!$U:$U,'Campaign - Dump'!$A:$A,Monthly!$A6) -> 3582316.4 | J6: =IFERROR(B6/I6,0) -> 0.15481379 | K6: =IFERROR(I6/G6,0) -> 18277.124 | L6: =IFERROR(I6/B6,0) -> 6.459373 | M6: =SUMIFS('Business - Dump'!$W:$W,'Business - Dump'!$A:$A,Monthly!$A6) -> 307 | N6: =SUMIFS('Business - Dump'!$U:$U,'Business - Dump'!$A:$A,Monthly!$A6)/1.18 -> 5105004 | O6: =IFERROR(N6/M6,0) -> 16628.678 | P6: =IFERROR(B6/N6,0) -> 0.10863693 | Q6: =IFERROR(N6/B6,0) -> 9.2049728 | R6: =IFERROR(M6-G6,0) -> 111 | S6: =IFERROR(N6-I6,0) -> 1522687.6 | T6: =IFERROR(S6/R6,0) -> 13717.906 | U6: =SUMIFS('Business - Dump'!$G:$G,'Business - Dump'!$A:$A,Monthly!$A6) -> 44385 | V6: =IFERROR(M6/U6,0) -> 0.0069167512 | W6: =AVERAGEIFS('Business - Dump'!$O:$O,'Business - Dump'!$A:$A,Monthly!$A6) -> 0.89423729 | X6: =R6/G6 -> 0.56632653 | Y6: =IFERROR(R6/M6,0) -> 0.36156352 | Z6: =IFERROR(S6/N6,0) -> 0.29827354 | AA6: =SUMIFS('Business - Dump'!$R:$R,'Business - Dump'!$A:$A,Monthly!$A6) -> 44 | AB6: =SUMIFS('Business - Dump'!$V:$V,'Business - Dump'!$A:$A,Monthly!$A6) -> 750380.73
A7: Apr | B7: =SUMIFS('Campaign - Dump'!$Q:$Q,'Campaign - Dump'!$A:$A,Monthly!$A7) -> 636539.97 | C7: =SUMIFS('Campaign - Dump'!$N:$N,'Campaign - Dump'!$A:$A,Monthly!$A7) -> 5671901 | D7: =IFERROR(E7/C7,0) -> 0.0044567068 | E7: =SUMIFS('Campaign - Dump'!$O:$O,'Campaign - Dump'!$A:$A,Monthly!$A7) -> 25278 | F7: =IFERROR(B7/E7,0) -> 25.18158 | G7: =SUMIFS('Campaign - Dump'!$T:$T,'Campaign - Dump'!$A:$A,Monthly!$A7) -> 192 | H7: =IFERROR(G7/E7,0) -> 0.0075955376 | I7: =SUMIFS('Campaign - Dump'!$U:$U,'Campaign - Dump'!$A:$A,Monthly!$A7) -> 3539616 | J7: =IFERROR(B7/I7,0) -> 0.17983306 | K7: =IFERROR(I7/G7,0) -> 18435.5 | L7: =IFERROR(I7/B7,0) -> 5.5607128 | M7: =SUMIFS('Business - Dump'!$W:$W,'Business - Dump'!$A:$A,Monthly!$A7) -> 280 | N7: =SUMIFS('Business - Dump'!$U:$U,'Business - Dump'!$A:$A,Monthly!$A7)/1.18 -> 4575649.8 | O7: =IFERROR(N7/M7,0) -> 16341.607 | P7: =IFERROR(B7/N7,0) -> 0.13911466 | Q7: =IFERROR(N7/B7,0) -> 7.1883151 | R7: =IFERROR(M7-G7,0) -> 88 | S7: =IFERROR(N7-I7,0) -> 1036033.9 | T7: =IFERROR(S7/R7,0) -> 11773.112 | U7: =SUMIFS('Business - Dump'!$G:$G,'Business - Dump'!$A:$A,Monthly!$A7) -> 46985 | V7: =IFERROR(M7/U7,0) -> 0.0059593487 | W7: =AVERAGEIFS('Business - Dump'!$O:$O,'Business - Dump'!$A:$A,Monthly!$A7) -> 0.87324717 | X7: =R7/G7 -> 0.45833333 | Y7: =IFERROR(R7/M7,0) -> 0.31428571 | Z7: =IFERROR(S7/N7,0) -> 0.22642333 | AA7: =SUMIFS('Business - Dump'!$R:$R,'Business - Dump'!$A:$A,Monthly!$A7) -> 40 | AB7: =SUMIFS('Business - Dump'!$V:$V,'Business - Dump'!$A:$A,Monthly!$A7) -> 838656.66
A8: May | B8: =SUMIFS('Campaign - Dump'!$Q:$Q,'Campaign - Dump'!$A:$A,Monthly!$A8) -> 915205.63 | C8: =SUMIFS('Campaign - Dump'!$N:$N,'Campaign - Dump'!$A:$A,Monthly!$A8) -> 6851490 | D8: =IFERROR(E8/C8,0) -> 0.0042012759 | E8: =SUMIFS('Campaign - Dump'!$O:$O,'Campaign - Dump'!$A:$A,Monthly!$A8) -> 28785 | F8: =IFERROR(B8/E8,0) -> 31.794533 | G8: =SUMIFS('Campaign - Dump'!$T:$T,'Campaign - Dump'!$A:$A,Monthly!$A8) -> 286 | H8: =IFERROR(G8/E8,0) -> 0.0099357304 | I8: =SUMIFS('Campaign - Dump'!$U:$U,'Campaign - Dump'!$A:$A,Monthly!$A8) -> 5240245.7 | J8: =IFERROR(B8/I8,0) -> 0.17464937 | K8: =IFERROR(I8/G8,0) -> 18322.538 | L8: =IFERROR(I8/B8,0) -> 5.7257578 | M8: =SUMIFS('Business - Dump'!$W:$W,'Business - Dump'!$A:$A,Monthly!$A8) -> 390 | N8: =SUMIFS('Business - Dump'!$U:$U,'Business - Dump'!$A:$A,Monthly!$A8)/1.18 -> 6681635.1 | O8: =IFERROR(N8/M8,0) -> 17132.398 | P8: =IFERROR(B8/N8,0) -> 0.1369733 | Q8: =IFERROR(N8/B8,0) -> 7.3006927 | R8: =IFERROR(M8-G8,0) -> 104 | S8: =IFERROR(N8-I8,0) -> 1441389.3 | T8: =IFERROR(S8/R8,0) -> 13859.513 | U8: =SUMIFS('Business - Dump'!$G:$G,'Business - Dump'!$A:$A,Monthly!$A8) -> 70627 | V8: =IFERROR(M8/U8,0) -> 0.0055219675 | W8: =AVERAGEIFS('Business - Dump'!$O:$O,'Business - Dump'!$A:$A,Monthly!$A8) -> 0.87631429 | X8: =R8/G8 -> 0.36363636 | Y8: =IFERROR(R8/M8,0) -> 0.26666667 | Z8: =IFERROR(S8/N8,0) -> 0.21572404 | AA8: =SUMIFS('Business - Dump'!$R:$R,'Business - Dump'!$A:$A,Monthly!$A8) -> 39 | AB8: =SUMIFS('Business - Dump'!$V:$V,'Business - Dump'!$A:$A,Monthly!$A8) -> 881601.36
A9: June | B9: =SUMIFS('Campaign - Dump'!$Q:$Q,'Campaign - Dump'!$A:$A,Monthly!$A9) -> 712488.04 | C9: =SUMIFS('Campaign - Dump'!$N:$N,'Campaign - Dump'!$A:$A,Monthly!$A9) -> 7449125 | D9: =IFERROR(E9/C9,0) -> 0.0035045727 | E9: =SUMIFS('Campaign - Dump'!$O:$O,'Campaign - Dump'!$A:$A,Monthly!$A9) -> 26106 | F9: =IFERROR(B9/E9,0) -> 27.292118 | G9: =SUMIFS('Campaign - Dump'!$T:$T,'Campaign - Dump'!$A:$A,Monthly!$A9) -> 220 | H9: =IFERROR(G9/E9,0) -> 0.0084271815 | I9: =SUMIFS('Campaign - Dump'!$U:$U,'Campaign - Dump'!$A:$A,Monthly!$A9) -> 3790348 | J9: =IFERROR(B9/I9,0) -> 0.18797431 | K9: =IFERROR(I9/G9,0) -> 17228.855 | L9: =IFERROR(I9/B9,0) -> 5.319876 | M9: =SUMIFS('Business - Dump'!$W:$W,'Business - Dump'!$A:$A,Monthly!$A9) -> 313 | N9: =SUMIFS('Business - Dump'!$U:$U,'Business - Dump'!$A:$A,Monthly!$A9)/1.18 -> 5290499 | O9: =IFERROR(N9/M9,0) -> 16902.553 | P9: =IFERROR(B9/N9,0) -> 0.13467313 | Q9: =IFERROR(N9/B9,0) -> 7.4253865 | R9: =IFERROR(M9-G9,0) -> 93 | S9: =IFERROR(N9-I9,0) -> 1500151 | T9: =IFERROR(S9/R9,0) -> 16130.656 | U9: =SUMIFS('Business - Dump'!$G:$G,'Business - Dump'!$A:$A,Monthly!$A9) -> 61268 | V9: =IFERROR(M9/U9,0) -> 0.0051087027 | W9: =AVERAGEIFS('Business - Dump'!$O:$O,'Business - Dump'!$A:$A,Monthly!$A9) -> 0.89095385 | X9: =R9/G9 -> 0.42272727 | Y9: =IFERROR(R9/M9,0) -> 0.2971246 | Z9: =IFERROR(S9/N9,0) -> 0.28355567 | AA9: =SUMIFS('Business - Dump'!$R:$R,'Business - Dump'!$A:$A,Monthly!$A9) -> 33 | AB9: =SUMIFS('Business - Dump'!$V:$V,'Business - Dump'!$A:$A,Monthly!$A9) -> 745221.97
A10: July | B10: =SUMIFS('Campaign - Dump'!$Q:$Q,'Campaign - Dump'!$A:$A,Monthly!$A10) -> 868070.3 | C10: =SUMIFS('Campaign - Dump'!$N:$N,'Campaign - Dump'!$A:$A,Monthly!$A10) -> 8194079 | D10: =IFERROR(E10/C10,0) -> 0.0035996724 | E10: =SUMIFS('Campaign - Dump'!$O:$O,'Campaign - Dump'!$A:$A,Monthly!$A10) -> 29496 | F10: =IFERROR(B10/E10,0) -> 29.430102 | G10: =SUMIFS('Campaign - Dump'!$T:$T,'Campaign - Dump'!$A:$A,Monthly!$A10) -> 279 | H10: =IFERROR(G10/E10,0) -> 0.0094589097 | I10: =SUMIFS('Campaign - Dump'!$U:$U,'Campaign - Dump'!$A:$A,Monthly!$A10) -> 5182218.6 | J10: =IFERROR(B10/I10,0) -> 0.16750939 | K10: =IFERROR(I10/G10,0) -> 18574.26 | L10: =IFERROR(I10/B10,0) -> 5.9698145 | M10: =SUMIFS('Business - Dump'!$W:$W,'Business - Dump'!$A:$A,Monthly!$A10) -> 411 | N10: =SUMIFS('Business - Dump'!$U:$U,'Business - Dump'!$A:$A,Monthly!$A10)/1.18 -> 7060713 | O10: =IFERROR(N10/M10,0) -> 17179.35 | P10: =IFERROR(B10/N10,0) -> 0.12294372 | Q10: =IFERROR(N10/B10,0) -> 8.1338033 | R10: =IFERROR(M10-G10,0) -> 132 | S10: =IFERROR(N10-I10,0) -> 1878494.4 | T10: =IFERROR(S10/R10,0) -> 14231.018 | U10: =SUMIFS('Business - Dump'!$G:$G,'Business - Dump'!$A:$A,Monthly!$A10) -> 65802 | V10: =IFERROR(M10/U10,0) -> 0.0062460108 | W10: =AVERAGEIFS('Business - Dump'!$O:$O,'Business - Dump'!$A:$A,Monthly!$A10) -> 0.83938409 | X10: =R10/G10 -> 0.47311828 | Y10: =IFERROR(R10/M10,0) -> 0.32116788 | Z10: =IFERROR(S10/N10,0) -> 0.26604882 | AA10: =SUMIFS('Business - Dump'!$R:$R,'Business - Dump'!$A:$A,Monthly!$A10) -> 31 | AB10: =SUMIFS('Business - Dump'!$V:$V,'Business - Dump'!$A:$A,Monthly!$A10) -> 623427.68
A11: August | B11: =SUMIFS('Campaign - Dump'!$Q:$Q,'Campaign - Dump'!$A:$A,Monthly!$A11) -> 831575.61 | C11: =SUMIFS('Campaign - Dump'!$N:$N,'Campaign - Dump'!$A:$A,Monthly!$A11) -> 7860313 | D11: =IFERROR(E11/C11,0) -> 0.0040125629 | E11: =SUMIFS('Campaign - Dump'!$O:$O,'Campaign - Dump'!$A:$A,Monthly!$A11) -> 31540 | F11: =IFERROR(B11/E11,0) -> 26.365745 | G11: =SUMIFS('Campaign - Dump'!$T:$T,'Campaign - Dump'!$A:$A,Monthly!$A11) -> 228 | H11: =IFERROR(G11/E11,0) -> 0.0072289157 | I11: =SUMIFS('Campaign - Dump'!$U:$U,'Campaign - Dump'!$A:$A,Monthly!$A11) -> 3896020.5 | J11: =IFERROR(B11/I11,0) -> 0.21344231 | K11: =IFERROR(I11/G11,0) -> 17087.809 | L11: =IFERROR(I11/B11,0) -> 4.6851068 | M11: =SUMIFS('Business - Dump'!$W:$W,'Business - Dump'!$A:$A,Monthly!$A11) -> 386 | N11: =SUMIFS('Business - Dump'!$U:$U,'Business - Dump'!$A:$A,Monthly!$A11)/1.18 -> 5948601.1 | O11: =IFERROR(N11/M11,0) -> 15410.884 | P11: =IFERROR(B11/N11,0) -> 0.13979347 | Q11: =IFERROR(N11/B11,0) -> 7.1534097 | R11: =IFERROR(M11-G11,0) -> 158 | S11: =IFERROR(N11-I11,0) -> 2052580.5 | T11: =IFERROR(S11/R11,0) -> 12991.016 | U11: =SUMIFS('Business - Dump'!$G:$G,'Business - Dump'!$A:$A,Monthly!$A11) -> 69611 | V11: =IFERROR(M11/U11,0) -> 0.0055451006 | W11: =AVERAGEIFS('Business - Dump'!$O:$O,'Business - Dump'!$A:$A,Monthly!$A11) -> 0.85197889 | X11: =R11/G11 -> 0.69298246 | Y11: =IFERROR(R11/M11,0) -> 0.40932642 | Z11: =IFERROR(S11/N11,0) -> 0.34505264 | AA11: =SUMIFS('Business - Dump'!$R:$R,'Business - Dump'!$A:$A,Monthly!$A11) -> 25 | AB11: =SUMIFS('Business - Dump'!$V:$V,'Business - Dump'!$A:$A,Monthly!$A11) -> 522851.94
A12: September | B12: =SUMIFS('Campaign - Dump'!$Q:$Q,'Campaign - Dump'!$A:$A,Monthly!$A12) -> 1390822.2 | C12: =SUMIFS('Campaign - Dump'!$N:$N,'Campaign - Dump'!$A:$A,Monthly!$A12) -> 14814452 | D12: =IFERROR(E12/C12,0) -> 0.0037431017 | E12: =SUMIFS('Campaign - Dump'!$O:$O,'Campaign - Dump'!$A:$A,Monthly!$A12) -> 55452 | F12: =IFERROR(B12/E12,0) -> 25.081552 | G12: =SUMIFS('Campaign - Dump'!$T:$T,'Campaign - Dump'!$A:$A,Monthly!$A12) -> 480 | H12: =IFERROR(G12/E12,0) -> 0.008656135 | I12: =SUMIFS('Campaign - Dump'!$U:$U,'Campaign - Dump'!$A:$A,Monthly!$A12) -> 7678468.1 | J12: =IFERROR(B12/I12,0) -> 0.18113277 | K12: =IFERROR(I12/G12,0) -> 15996.809 | L12: =IFERROR(I12/B12,0) -> 5.5208121 | M12: =SUMIFS('Business - Dump'!$W:$W,'Business - Dump'!$A:$A,Monthly!$A12) -> 683 | N12: =SUMIFS('Business - Dump'!$U:$U,'Business - Dump'!$A:$A,Monthly!$A12)/1.18 -> 10270914 | O12: =IFERROR(N12/M12,0) -> 15037.941 | P12: =IFERROR(B12/N12,0) -> 0.13541368 | Q12: =IFERROR(N12/B12,0) -> 7.3847784 | R12: =IFERROR(M12-G12,0) -> 203 | S12: =IFERROR(N12-I12,0) -> 2592445.8 | T12: =IFERROR(S12/R12,0) -> 12770.669 | U12: =SUMIFS('Business - Dump'!$G:$G,'Business - Dump'!$A:$A,Monthly!$A12) -> 92124 | V12: =IFERROR(M12/U12,0) -> 0.0074139204 | W12: =AVERAGEIFS('Business - Dump'!$O:$O,'Business - Dump'!$A:$A,Monthly!$A12) -> 0.89220123 | X12: =R12/G12 -> 0.42291667 | Y12: =IFERROR(R12/M12,0) -> 0.29721816 | Z12: =IFERROR(S12/N12,0) -> 0.25240654 | AA12: =SUMIFS('Business - Dump'!$R:$R,'Business - Dump'!$A:$A,Monthly!$A12) -> 54 | AB12: =SUMIFS('Business - Dump'!$V:$V,'Business - Dump'!$A:$A,Monthly!$A12) -> 940608.38
A13: October | B13: =SUMIFS('Campaign - Dump'!$Q:$Q,'Campaign - Dump'!$A:$A,Monthly!$A13) -> 1281599.9 | C13: =SUMIFS('Campaign - Dump'!$N:$N,'Campaign - Dump'!$A:$A,Monthly!$A13) -> 8094986 | D13: =IFERROR(E13/C13,0) -> 0.0036366956 | E13: =SUMIFS('Campaign - Dump'!$O:$O,'Campaign - Dump'!$A:$A,Monthly!$A13) -> 29439 | F13: =IFERROR(B13/E13,0) -> 43.534084 | G13: =SUMIFS('Campaign - Dump'!$T:$T,'Campaign - Dump'!$A:$A,Monthly!$A13) -> 348 | H13: =IFERROR(G13/E13,0) -> 0.011821054 | I13: =SUMIFS('Campaign - Dump'!$U:$U,'Campaign - Dump'!$A:$A,Monthly!$A13) -> 5884150.9 | J13: =IFERROR(B13/I13,0) -> 0.21780541 | K13: =IFERROR(I13/G13,0) -> 16908.48 | L13: =IFERROR(I13/B13,0) -> 4.5912542 | M13: =SUMIFS('Business - Dump'!$W:$W,'Business - Dump'!$A:$A,Monthly!$A13) -> 590 | N13: =SUMIFS('Business - Dump'!$U:$U,'Business - Dump'!$A:$A,Monthly!$A13)/1.18 -> 8563706.4 | O13: =IFERROR(N13/M13,0) -> 14514.757 | P13: =IFERROR(B13/N13,0) -> 0.14965481 | Q13: =IFERROR(N13/B13,0) -> 6.6820437 | R13: =IFERROR(M13-G13,0) -> 242 | S13: =IFERROR(N13-I13,0) -> 2679555.5 | T13: =IFERROR(S13/R13,0) -> 11072.543 | U13: =SUMIFS('Business - Dump'!$G:$G,'Business - Dump'!$A:$A,Monthly!$A13) -> 72627 | V13: =IFERROR(M13/U13,0) -> 0.0081237006 | W13: =AVERAGEIFS('Business - Dump'!$O:$O,'Business - Dump'!$A:$A,Monthly!$A13) -> 0.86028936 | X13: =R13/G13 -> 0.6954023 | Y13: =IFERROR(R13/M13,0) -> 0.41016949 | Z13: =IFERROR(S13/N13,0) -> 0.3128967 | AA13: =SUMIFS('Business - Dump'!$R:$R,'Business - Dump'!$A:$A,Monthly!$A13) -> 34 | AB13: =SUMIFS('Business - Dump'!$V:$V,'Business - Dump'!$A:$A,Monthly!$A13) -> 548954.95
... A15: December | B15: =SUMIFS('Campaign - Dump'!$Q:$Q,'Campaign - Dump'!$A:$A,Monthly!$A15) -> 660076.26 | C15: =SUMIFS('Campaign - Dump'!$N:$N,'Campaign - Dump'!$A:$A,Monthly!$A15) -> 7845997 | D15: =IFERROR(E15/C15,0) -> 0.0046747405 | E15: =SUMIFS('Campaign - Dump'!$O:$O,'Campaign - Dump'!$A:$A,Monthly!$A15) -> 36678 | F15: =IFERROR(B15/E15,0) -> 17.996517 | G15: =SUMIFS('Campaign - Dump'!$T:$T,'Campaign - Dump'!$A:$A,Monthly!$A15) -> 301 | H15: =IFERROR(G15/E15,0) -> 0.0082065543 | I15: =SUMIFS('Campaign - Dump'!$U:$U,'Campaign - Dump'!$A:$A,Monthly!$A15) -> 2744575.4 | J15: =IFERROR(B15/I15,0) -> 0.24050214 | K15: =IFERROR(I15/G15,0) -> 9118.1908 | L15: =IFERROR(I15/B15,0) -> 4.1579672 | M15: =SUMIFS('Business - Dump'!$W:$W,'Business - Dump'!$A:$A,Monthly!$A15) -> 471 | N15: =SUMIFS('Business - Dump'!$U:$U,'Business - Dump'!$A:$A,Monthly!$A15)/1.18 -> 4159256 | O15: =IFERROR(N15/M15,0) -> 8830.6921 | P15: =IFERROR(B15/N15,0) -> 0.15870056 | Q15: =IFERROR(N15/B15,0) -> 6.301175 | R15: =IFERROR(M15-G15,0) -> 170 | S15: =IFERROR(N15-I15,0) -> 1414680.6 | T15: =IFERROR(S15/R15,0) -> 8321.6504 | U15: =SUMIFS('Business - Dump'!$G:$G,'Business - Dump'!$A:$A,Monthly!$A15) -> 68314 | V15: =IFERROR(M15/U15,0) -> 0.0068946336 | W15: =AVERAGEIFS('Business - Dump'!$O:$O,'Business - Dump'!$A:$A,Monthly!$A15) -> 0.88491684 | X15: =R15/G15 -> 0.56478405 | Y15: =IFERROR(R15/M15,0) -> 0.36093418 | Z15: =IFERROR(S15/N15,0) -> 0.34012827 | AA15: =SUMIFS('Business - Dump'!$R:$R,'Business - Dump'!$A:$A,Monthly!$A15) -> 35 | AB15: =SUMIFS('Business - Dump'!$V:$V,'Business - Dump'!$A:$A,Monthly!$A15) -> 473397.68
A16: 45658 | B16: =SUMIFS('Campaign - Dump'!$Q:$Q,'Campaign - Dump'!$A:$A,Monthly!$A16) -> 743314.92 | C16: =SUMIFS('Campaign - Dump'!$N:$N,'Campaign - Dump'!$A:$A,Monthly!$A16) -> 6106324 | D16: =IFERROR(E16/C16,0) -> 0.0051885553 | E16: =SUMIFS('Campaign - Dump'!$O:$O,'Campaign - Dump'!$A:$A,Monthly!$A16) -> 31683 | F16: =IFERROR(B16/E16,0) -> 23.461002 | G16: =SUMIFS('Campaign - Dump'!$T:$T,'Campaign - Dump'!$A:$A,Monthly!$A16) -> 292 | H16: =IFERROR(G16/E16,0) -> 0.009216299 | I16: =SUMIFS('Campaign - Dump'!$U:$U,'Campaign - Dump'!$A:$A,Monthly!$A16) -> 3410399.2 | J16: =IFERROR(B16/I16,0) -> 0.2179554 | K16: =IFERROR(I16/G16,0) -> 11679.449 | L16: =IFERROR(I16/B16,0) -> 4.5880946 | M16: =SUMIFS('Business - Dump'!$W:$W,'Business - Dump'!$A:$A,Monthly!$A16) -> 428 | N16: =SUMIFS('Business - Dump'!$U:$U,'Business - Dump'!$A:$A,Monthly!$A16)/1.18 -> 5082627.8 | O16: =IFERROR(N16/M16,0) -> 11875.299 | P16: =IFERROR(B16/N16,0) -> 0.14624618 | Q16: =IFERROR(N16/B16,0) -> 6.8377852 | R16: =IFERROR(M16-G16,0) -> 136 | S16: =IFERROR(N16-I16,0) -> 1672228.6 | T16: =IFERROR(S16/R16,0) -> 12295.799 | U16: =SUMIFS('Business - Dump'!$G:$G,'Business - Dump'!$A:$A,Monthly!$A16) -> 59954 | V16: =IFERROR(M16/U16,0) -> 0.0071388064 | W16: =AVERAGEIFS('Business - Dump'!$O:$O,'Business - Dump'!$A:$A,Monthly!$A16) -> 0.88701348 | X16: =R16/G16 -> 0.46575342 | Y16: =IFERROR(R16/M16,0) -> 0.31775701 | Z16: =IFERROR(S16/N16,0) -> 0.32900867 | AA16: =SUMIFS('Business - Dump'!$R:$R,'Business - Dump'!$A:$A,Monthly!$A16) -> 50 | AB16: =SUMIFS('Business - Dump'!$V:$V,'Business - Dump'!$A:$A,Monthly!$A16) -> 563631.61
A17: 45689 | B17: =SUMIFS('Campaign - Dump'!$Q:$Q,'Campaign - Dump'!$A:$A,Monthly!$A17) -> 645642.5 | C17: =SUMIFS('Campaign - Dump'!$N:$N,'Campaign - Dump'!$A:$A,Monthly!$A17) -> 6128191 | D17: =IFERROR(E17/C17,0) -> 0.0051989241 | E17: =SUMIFS('Campaign - Dump'!$O:$O,'Campaign - Dump'!$A:$A,Monthly!$A17) -> 31860 | F17: =IFERROR(B17/E17,0) -> 20.264987 | G17: =SUMIFS('Campaign - Dump'!$T:$T,'Campaign - Dump'!$A:$A,Monthly!$A17) -> 345 | H17: =IFERROR(G17/E17,0) -> 0.010828625 | I17: =SUMIFS('Campaign - Dump'!$U:$U,'Campaign - Dump'!$A:$A,Monthly!$A17) -> 2448692.5 | J17: =IFERROR(B17/I17,0) -> 0.26366827 | K17: =IFERROR(I17/G17,0) -> 7097.6594 | L17: =IFERROR(I17/B17,0) -> 3.7926445 | M17: =SUMIFS('Business - Dump'!$W:$W,'Business - Dump'!$A:$A,Monthly!$A17) -> 478 | N17: =SUMIFS('Business - Dump'!$U:$U,'Business - Dump'!$A:$A,Monthly!$A17)/1.18 -> 3545813 | O17: =IFERROR(N17/M17,0) -> 7418.0188 | P17: =IFERROR(B17/N17,0) -> 0.18208589 | Q17: =IFERROR(N17/B17,0) -> 5.4919138 | R17: =IFERROR(M17-G17,0) -> 133 | S17: =IFERROR(N17-I17,0) -> 1097120.5 | T17: =IFERROR(S17/R17,0) -> 8249.0262 | U17: =SUMIFS('Business - Dump'!$G:$G,'Business - Dump'!$A:$A,Monthly!$A17) -> 59264 | V17: =IFERROR(M17/U17,0) -> 0.0080656048 | W17: =AVERAGEIFS('Business - Dump'!$O:$O,'Business - Dump'!$A:$A,Monthly!$A17) -> 0.89536705 | X17: =R17/G17 -> 0.38550725 | Y17: =IFERROR(R17/M17,0) -> 0.27824268 | Z17: =IFERROR(S17/N17,0) -> 0.30941296 | AA17: =SUMIFS('Business - Dump'!$R:$R,'Business - Dump'!$A:$A,Monthly!$A17) -> 54 | AB17: =SUMIFS('Business - Dump'!$V:$V,'Business - Dump'!$A:$A,Monthly!$A17) -> 541480.81
A18: 45717 | B18: =SUMIFS('Campaign - Dump'!$Q:$Q,'Campaign - Dump'!$A:$A,Monthly!$A18) -> 845513.7 | C18: =SUMIFS('Campaign - Dump'!$N:$N,'Campaign - Dump'!$A:$A,Monthly!$A18) -> 11643879 | D18: =IFERROR(E18/C18,0) -> 0.0044048895 | E18: =SUMIFS('Campaign - Dump'!$O:$O,'Campaign - Dump'!$A:$A,Monthly!$A18) -> 51290 | F18: =IFERROR(B18/E18,0) -> 16.484962 | G18: =SUMIFS('Campaign - Dump'!$T:$T,'Campaign - Dump'!$A:$A,Monthly!$A18) -> 458 | H18: =IFERROR(G18/E18,0) -> 0.0089296159 | I18: =SUMIFS('Campaign - Dump'!$U:$U,'Campaign - Dump'!$A:$A,Monthly!$A18) -> 3495437.8 | J18: =IFERROR(B18/I18,0) -> 0.24189064 | K18: =IFERROR(I18/G18,0) -> 7631.9603 | L18: =IFERROR(I18/B18,0) -> 4.1340995 | M18: =SUMIFS('Business - Dump'!$W:$W,'Business - Dump'!$A:$A,Monthly!$A18) -> 626 | N18: =SUMIFS('Business - Dump'!$U:$U,'Business - Dump'!$A:$A,Monthly!$A18)/1.18 -> 5083935.1 | O18: =IFERROR(N18/M18,0) -> 8121.3021 | P18: =IFERROR(B18/N18,0) -> 0.16631088 | Q18: =IFERROR(N18/B18,0) -> 6.0128359 | R18: =IFERROR(M18-G18,0) -> 168 | S18: =IFERROR(N18-I18,0) -> 1588497.3 | T18: =IFERROR(S18/R18,0) -> 9455.341 | U18: =SUMIFS('Business - Dump'!$G:$G,'Business - Dump'!$A:$A,Monthly!$A18) -> 76596 | V18: =IFERROR(M18/U18,0) -> 0.0081727505 | W18: =AVERAGEIFS('Business - Dump'!$O:$O,'Business - Dump'!$A:$A,Monthly!$A18) -> 0.88509149 | X18: =R18/G18 -> 0.36681223 | Y18: =IFERROR(R18/M18,0) -> 0.26837061 | Z18: =IFERROR(S18/N18,0) -> 0.31245428 | AA18: =SUMIFS('Business - Dump'!$R:$R,'Business - Dump'!$A:$A,Monthly!$A18) -> 49 | AB18: =SUMIFS('Business - Dump'!$V:$V,'Business - Dump'!$A:$A,Monthly!$A18) -> 571076.99
A19: 45772 | B19: =SUMIFS('Campaign - Dump'!$Q:$Q,'Campaign - Dump'!$A:$A,Monthly!$A19) -> 733459.69 | C19: =SUMIFS('Campaign - Dump'!$N:$N,'Campaign - Dump'!$A:$A,Monthly!$A19) -> 9553651 | D19: =IFERROR(E19/C19,0) -> 0.004356345 | E19: =SUMIFS('Campaign - Dump'!$O:$O,'Campaign - Dump'!$A:$A,Monthly!$A19) -> 41619 | F19: =IFERROR(B19/E19,0) -> 17.623193 | G19: =SUMIFS('Campaign - Dump'!$T:$T,'Campaign - Dump'!$A:$A,Monthly!$A19) -> 285 | H19: =IFERROR(G19/E19,0) -> 0.0068478339 | I19: =SUMIFS('Campaign - Dump'!$U:$U,'Campaign - Dump'!$A:$A,Monthly!$A19) -> 2820948.6 | J19: =IFERROR(B19/I19,0) -> 0.26000463 | K19: =IFERROR(I19/G19,0) -> 9898.0651 | L19: =IFERROR(I19/B19,0) -> 3.8460853 | M19: =SUMIFS('Business - Dump'!$W:$W,'Business - Dump'!$A:$A,Monthly!$A19) -> 433 | N19: =SUMIFS('Business - Dump'!$U:$U,'Business - Dump'!$A:$A,Monthly!$A19)/1.18 -> 4434956.3 | O19: =IFERROR(N19/M19,0) -> 10242.393 | P19: =IFERROR(B19/N19,0) -> 0.16538149 | Q19: =IFERROR(N19/B19,0) -> 6.0466258 | R19: =IFERROR(M19-G19,0) -> 148 | S19: =IFERROR(N19-I19,0) -> 1614007.8 | T19: =IFERROR(S19/R19,0) -> 10905.458 | U19: =SUMIFS('Business - Dump'!$G:$G,'Business - Dump'!$A:$A,Monthly!$A19) -> 65083 | V19: =IFERROR(M19/U19,0) -> 0.006653043 | W19: =AVERAGEIFS('Business - Dump'!$O:$O,'Business - Dump'!$A:$A,Monthly!$A19) -> 0.88995604 | X19: =R19/G19 -> 0.51929825 | Y19: =IFERROR(R19/M19,0) -> 0.34180139 | Z19: =IFERROR(S19/N19,0) -> 0.36392867 | AA19: =SUMIFS('Business - Dump'!$R:$R,'Business - Dump'!$A:$A,Monthly!$A19) -> 41 | AB19: =SUMIFS('Business - Dump'!$V:$V,'Business - Dump'!$A:$A,Monthly!$A19) -> 633049.26
A20: ='Portfolio Wise '!A470 -> 25_May | B20: ='Portfolio Wise '!F470 -> 900000 | C20: ='Portfolio Wise '!C470 -> 11739457 | D20: ='Portfolio Wise '!E470 -> 0.0042133451 | E20: ='Portfolio Wise '!D470 -> 49462.385 | F20: ='Portfolio Wise '!G470 -> 18.195645 | G20: ='Portfolio Wise '!H470 -> 351.28683 | H20: ='Portfolio Wise '!I470 -> 0.0071021006 | I20: ='Portfolio Wise '!J470 -> 3484490.2 | J20: ='Portfolio Wise '!K470 -> 0.25828743 | K20: ='Portfolio Wise '!M470 -> 9919.2166 | L20: ='Portfolio Wise '!L470 -> 3.8716558 | M20: ='Portfolio Wise '!Q470 -> 457.76315 | N20: ='Portfolio Wise '!R470 -> 2786957.7 | O20: ='Portfolio Wise '!S470 -> 6088.2089 | P20: ='Portfolio Wise '!T470 -> 0.32293278 | Q20: ='Portfolio Wise '!U470 -> 3.0966196 | R20: ='Portfolio Wise '!N470 -> 106.47631 | S20: ='Portfolio Wise '!O470 -> 955427.94 | T20: ='Portfolio Wise '!P470 -> 8973.1501 | X20: =R20/G20 -> 0.30310363 | Y20: =IFERROR(R20/M20,0) -> 0.23260132 | Z20: =IFERROR(S20/N20,0) -> 0.34282112

Sheet Qtr - Report 
A1: Q | B1: Amt Spent | C1: Imp | D1: CTR | E1: Clicks | F1: CPC | G1: Paid Orders | H1: CR | I1: Paid Revenue | J1: Paid ACOS | K1: Paid AOV | L1: ROAS | M1: Total Orders | N1: Total Sale | O1: Total AOV | P1: TACOS | Q1: ROI | R1: Organic Orders | S1: Organic Sale | T1: Organic AOV | U1: Sessions | V1: Session %
A2: Q1 | B2: =SUM(Monthly!B4:B6) -> 1187748.6 | C2: =SUM(Monthly!C4:C6) -> 11837783 | D2: =IFERROR(E2/C2,0) -> 0.0045487402 | E2: =SUM(Monthly!E4:E6) -> 53847 | F2: =IFERROR(B2/E2,0) -> 22.057841 | G2: =SUM(Monthly!G4:G6) -> 401 | H2: =IFERROR(G2/E2,0) -> 0.0074470258 | I2: =SUM(Monthly!I4:I6) -> 7311707.1 | J2: =IFERROR(B2/I2,0) -> 0.16244477 | K2: =IFERROR(I2/G2,0) -> 18233.683 | L2: =IFERROR(I2/B2,0) -> 6.1559383 | M2: =SUM(Monthly!M4:M6) -> 691 | N2: =SUM(Monthly!N4:N6) -> 11127431 | O2: =IFERROR(N2/M2,0) -> 16103.374 | P2: =IFERROR(B2/N2,0) -> 0.10674059 | Q2: =IFERROR(N2/B2,0) -> 9.3685071 | R2: =IFERROR(M2-G2,0) -> 290 | S2: =IFERROR(N2-I2,0) -> 3815724.1 | T2: =IFERROR(S2/R2,0) -> 13157.669 | U2: =SUM(Monthly!U4:U6) -> 102716 | V2: =IFERROR(M2/U2,0) -> 0.0067272869
A3: Q2 | B3: =SUM(Monthly!B6:B8) -> 2106337.6 | C3: =SUM(Monthly!C6:C8) -> 17707795 | D3: =IFERROR(E3/C3,0) -> 0.0045273282 | E3: =SUM(Monthly!E7:E9) -> 80169 | F3: =IFERROR(B3/E3,0) -> 26.273716 | G3: =SUM(Monthly!G7:G9) -> 698 | H3: =IFERROR(G3/E3,0) -> 0.0087066073 | I3: =SUM(Monthly!I6:I8) -> 12362178 | J3: =IFERROR(B3/I3,0) -> 0.17038564 | K3: =IFERROR(I3/G3,0) -> 17710.857 | L3: =IFERROR(I3/B3,0) -> 5.8690393 | M3: =SUM(Monthly!M7:M9) -> 983 | N3: =SUM(Monthly!N7:N9) -> 16547784 | O3: =IFERROR(N3/M3,0) -> 16833.961 | P3: =IFERROR(B3/N3,0) -> 0.1272882 | Q3: =IFERROR(N3/B3,0) -> 7.856188 | R3: =IFERROR(M3-G3,0) -> 285 | S3: =IFERROR(N3-I3,0) -> 4185605.9 | T3: =IFERROR(S3/R3,0) -> 14686.336 | U3: =SUM(Monthly!U6:U8) -> 161997 | V3: =IFERROR(M3/U3,0) -> 0.0060680136
A4: Q3 | B4: =SUM(Monthly!B10:B12) -> 3090468.1 | C4: =SUM(Monthly!C7:C9) -> 19972516 | D4: =IFERROR(E4/C4,0) -> 0.0058324149 | E4: =SUM(Monthly!E10:E12) -> 116488 | F4: =IFERROR(B4/E4,0) -> 26.530356 | G4: =SUM(Monthly!G10:G12) -> 987 | H4: =IFERROR(G4/E4,0) -> 0.0084729758 | I4: =SUM(Monthly!I7:I9) -> 12570210 | J4: =IFERROR(B4/I4,0) -> 0.24585653 | K4: =IFERROR(I4/G4,0) -> 12735.775 | L4: =IFERROR(I4/B4,0) -> 4.0674128 | M4: =SUM(Monthly!M10:M12) -> 1480 | N4: =SUM(Monthly!N10:N12) -> 23280228 | O4: =IFERROR(N4/M4,0) -> 15729.884 | P4: =IFERROR(B4/N4,0) -> 0.13275077 | Q4: =IFERROR(N4/B4,0) -> 7.5329131 | R4: =IFERROR(M4-G4,0) -> 493 | S4: =IFERROR(N4-I4,0) -> 10710018 | T4: =IFERROR(S4/R4,0) -> 21724.175 | U4: =SUM(Monthly!U7:U9) -> 178880 | V4: =IFERROR(M4/U4,0) -> 0.008273703
A8: Month | B8: Amt Spent | C8: Imp | D8: CTR | E8: Clicks | F8: CPC | G8: Paid Orders | H8: CR | I8: Paid Revenue | J8: Paid ACOS | K8: Paid AOV | L8: ROAS | M8: Total Orders | N8: Total Sale | O8: Total AOV | P8: TACOS | Q8: ROI | R8: Organic Orders | S8: Organic Sale | T8: Organic AOV | U8: Sessions | V8: Session %
A9: Jan | B9: 269951.38 | C9: 3237665 | D9: 0.0041446536 | E9: 13419 | F9: 20.117101 | G9: 82 | H9: 0.0061107385 | I9: 1526285 | J9: 0.17686827 | K9: 18613.231 | L9: 5.6539255 | M9: 156 | N9: 2496815.5 | O9: 16005.228 | P9: 0.10811827 | Q9: 9.2491304 | R9: 74 | S9: 970530.53 | T9: 13115.277 | U9: 26612 | V9: 0.0058620171
A10: Feb | B10: 363205.24 | C10: 3415714 | D10: 0.0046774993 | E10: 15977 | F10: 22.733006 | G10: 123 | H10: 0.0076985667 | I10: 2203105.7 | J10: 0.16486056 | K10: 17911.429 | L10: 6.0657322 | M10: 228 | N10: 3525611.6 | O10: 15463.209 | P10: 0.10301907 | Q10: 9.7069404 | R10: 105 | S10: 1322505.9 | T10: 12595.294 | U10: 31719 | V10: 0.0071881207
A11: Mar | B11: 554591.97 | C11: 5184404 | D11: 0.0047162605 | E11: 24451 | F11: 22.68177 | G11: 196 | H11: 0.0080160321 | I11: 3582316.4 | J11: 0.15481379 | K11: 18277.124 | L11: 6.459373 | M11: 307 | N11: 5105004 | O11: 16628.678 | P11: 0.10863693 | Q11: 9.2049728 | R11: 111 | S11: 1522687.6 | T11: 13717.906 | U11: 44385 | V11: 0.0069167512
A12: Apr | B12: 636539.97 | C12: 5671901 | D12: 0.0044567068 | E12: 25278 | F12: 25.18158 | G12: 192 | H12: 0.0075955376 | I12: 3539616 | J12: 0.17983306 | K12: 18435.5 | L12: 5.5607128 | M12: 280 | N12: 4575649.8 | O12: 16341.607 | P12: 0.13911466 | Q12: 7.1883151 | R12: 88 | S12: 1036033.9 | T12: 11773.112 | U12: 46985 | V12: 0.0059593487
A13: May | B13: 915205.63 | C13: 6851490 | D13: 0.0042012759 | E13: 28785 | F13: 31.794533 | G13: 286 | H13: 0.0099357304 | I13: 5240245.7 | J13: 0.17464937 | K13: 18322.538 | L13: 5.7257578 | M13: 390 | N13: 6681635.1 | O13: 17132.398 | P13: 0.1369733 | Q13: 7.3006927 | R13: 104 | S13: 1441389.3 | T13: 13859.513 | U13: 70627 | V13: 0.0055219675
A14: June | B14: 712488.04 | C14: 7449125 | D14: 0.0035045727 | E14: 26106 | F14: 27.292118 | G14: 220 | H14: 0.0084271815 | I14: 3790348 | J14: 0.18797431 | K14: 17228.855 | L14: 5.319876 | M14: 313 | N14: 5290499 | O14: 16902.553 | P14: 0.13467313 | Q14: 7.4253865 | R14: 93 | S14: 1500151 | T14: 16130.656 | U14: 61268 | V14: 0.0051087027
A15: July | B15: 868070.3 | C15: 8194079 | D15: 0.0035996724 | E15: 29496 | F15: 29.430102 | G15: 279 | H15: 0.0094589097 | I15: 5182218.6 | J15: 0.16750939 | K15: 18574.26 | L15: 5.9698145 | M15: 411 | N15: 7060713 | O15: 17179.35 | P15: 0.12294372 | Q15: 8.1338033 | R15: 132 | S15: 1878494.4 | T15: 14231.018 | U15: 65802 | V15: 0.0062460108
A16: August | B16: 831575.61 | C16: 7860313 | D16: 0.0040125629 | E16: 31540 | F16: 26.365745 | G16: 228 | H16: 0.0072289157 | I16: 3896020.5 | J16: 0.21344231 | K16: 17087.809 | L16: 4.6851068 | M16: 386 | N16: 5948601.1 | O16: 15410.884 | P16: 0.13979347 | Q16: 7.1534097 | R16: 158 | S16: 2052580.5 | T16: 12991.016 | U16: 69611 | V16: 0.0055451006
A17: September | B17: 1390822.2 | C17: 14814452 | D17: 0.0037431017 | E17: 55452 | F17: 25.081552 | G17: 480 | H17: 0.008656135 | I17: 7678468.1 | J17: 0.18113277 | K17: 15996.809 | L17: 5.5208121 | M17: 683 | N17: 10270914 | O17: 15037.941 | P17: 0.13541368 | Q17: 7.3847784 | R17: 203 | S17: 2592445.8 | T17: 12770.669 | U17: 92124 | V17: 0.0074139204

Sheet B2B 
A1: Month | B1: Order | C1: Order | D1: Order B2B | E1: Sales - B2B
A2: Nov | B2: 107 | C2: 2169972 | D2: =SUMIFS('Business - Dump'!$R:$R,'Business - Dump'!$A:$A,'B2B '!$A2) -> 8 | E2: 195598
A3: Dec | B3: 214 | C3: 4260008 | D3: =SUMIFS('Business - Dump'!$R:$R,'Business - Dump'!$A:$A,'B2B '!$A3) -> 18 | E3: 396598
A4: Jan | B4: 156 | C4: 2946242.3 | D4: =SUMIFS('Business - Dump'!$R:$R,'Business - Dump'!$A:$A,'B2B '!$A4) -> 16 | E4: 265894.4
A5: Feb | B5: 228 | C5: 4160221.7 | D5: =SUMIFS('Business - Dump'!$R:$R,'Business - Dump'!$A:$A,'B2B '!$A5) -> 17 | E5: 369473.29
A6: Mar | B6: 307 | C6: 6023904.7 | D6: =SUMIFS('Business - Dump'!$R:$R,'Business - Dump'!$A:$A,'B2B '!$A6) -> 44 | E6: 750380.73
A7: Apr | B7: =SUMIFS('Business - Dump'!$W:$W,'Business - Dump'!$A:$A,'B2B '!$A7)-D7 -> 255 | C7: =SUMIFS('Business - Dump'!$U:$U,'Business - Dump'!$A:$A,'B2B '!$A7)-E7 -> 4560610.2 | D7: =SUMIFS('Business - Dump'!$X:$X,'Business - Dump'!$A:$A,'B2B '!$A7) -> 25 | E7: =SUMIFS('Business - Dump'!$V:$V,'Business - Dump'!$A:$A,'B2B '!$A7) -> 838656.66
A8: May | B8: =SUMIFS('Business - Dump'!$W:$W,'Business - Dump'!$A:$A,'B2B '!$A8)-D8 -> 354 | C8: =SUMIFS('Business - Dump'!$U:$U,'Business - Dump'!$A:$A,'B2B '!$A8)-E8 -> 7002728 | D8: =SUMIFS('Business - Dump'!$X:$X,'Business - Dump'!$A:$A,'B2B '!$A8) -> 36 | E8: =SUMIFS('Business - Dump'!$V:$V,'Business - Dump'!$A:$A,'B2B '!$A8) -> 881601.36
A9: June | B9: =SUMIFS('Business - Dump'!$W:$W,'Business - Dump'!$A:$A,'B2B '!$A9)-D9 -> 282 | C9: =SUMIFS('Business - Dump'!$U:$U,'Business - Dump'!$A:$A,'B2B '!$A9)-E9 -> 5497566.9 | D9: =SUMIFS('Business - Dump'!$X:$X,'Business - Dump'!$A:$A,'B2B '!$A9) -> 31 | E9: =SUMIFS('Business - Dump'!$V:$V,'Business - Dump'!$A:$A,'B2B '!$A9) -> 745221.97
A10: July | B10: =SUMIFS('Business - Dump'!$W:$W,'Business - Dump'!$A:$A,'B2B '!$A10)-D10 -> 380 | C10: =SUMIFS('Business - Dump'!$U:$U,'Business - Dump'!$A:$A,'B2B '!$A10)-E10 -> 7708213.7 | D10: =SUMIFS('Business - Dump'!$X:$X,'Business - Dump'!$A:$A,'B2B '!$A10) -> 31 | E10: =SUMIFS('Business - Dump'!$V:$V,'Business - Dump'!$A:$A,'B2B '!$A10) -> 623427.68
A11: August | B11: =SUMIFS('Business - Dump'!$W:$W,'Business - Dump'!$A:$A,'B2B '!$A11)-D11 -> 361 | C11: =SUMIFS('Business - Dump'!$U:$U,'Business - Dump'!$A:$A,'B2B '!$A11)-E11 -> 6496497.3 | D11: =SUMIFS('Business - Dump'!$X:$X,'Business - Dump'!$A:$A,'B2B '!$A11) -> 25 | E11: =SUMIFS('Business - Dump'!$V:$V,'Business - Dump'!$A:$A,'B2B '!$A11) -> 522851.94
A12: September | B12: =SUMIFS('Business - Dump'!$W:$W,'Business - Dump'!$A:$A,'B2B '!$A12)-D12 -> 631 | C12: =SUMIFS('Business - Dump'!$U:$U,'Business - Dump'!$A:$A,'B2B '!$A12)-E12 -> 11179070 | D12: =SUMIFS('Business - Dump'!$X:$X,'Business - Dump'!$A:$A,'B2B '!$A12) -> 52 | E12: =SUMIFS('Business - Dump'!$V:$V,'Business - Dump'!$A:$A,'B2B '!$A12) -> 940608.38
A13: October | B13: =SUMIFS('Business - Dump'!$W:$W,'Business - Dump'!$A:$A,'B2B '!$A13)-D13 -> 558 | C13: =SUMIFS('Business - Dump'!$U:$U,'Business - Dump'!$A:$A,'B2B '!$A13)-E13 -> 9556218.7 | D13: =SUMIFS('Business - Dump'!$X:$X,'Business - Dump'!$A:$A,'B2B '!$A13) -> 32 | E13: =SUMIFS('Business - Dump'!$V:$V,'Business - Dump'!$A:$A,'B2B '!$A13) -> 548954.95
A14: November | B14: =SUMIFS('Business - Dump'!$W:$W,'Business - Dump'!$A:$A,'B2B '!$A14)-D14 -> 349 | C14: =SUMIFS('Business - Dump'!$U:$U,'Business - Dump'!$A:$A,'B2B '!$A14)-E14 -> 4378557.4 | D14: =SUMIFS('Business - Dump'!$X:$X,'Business - Dump'!$A:$A,'B2B '!$A14) -> 30 | E14: =SUMIFS('Business - Dump'!$V:$V,'Business - Dump'!$A:$A,'B2B '!$A14) -> 562434.45
A15: December | B15: =SUMIFS('Business - Dump'!$W:$W,'Business - Dump'!$A:$A,'B2B '!$A15)-D15 -> 441 | C15: =SUMIFS('Business - Dump'!$U:$U,'Business - Dump'!$A:$A,'B2B '!$A15)-E15 -> 4434524.4 | D15: =SUMIFS('Business - Dump'!$X:$X,'Business - Dump'!$A:$A,'B2B '!$A15) -> 30 | E15: =SUMIFS('Business - Dump'!$V:$V,'Business - Dump'!$A:$A,'B2B '!$A15) -> 473397.68
A16: Total | B16: =SUM(B2:B11) -> 2644 | C16: =SUM(C2:C11) -> 50825965 | D16: =SUM(D2:D11) -> 251 | E16: =SUM(E2:E11) -> 5589704

Sheet Portfolio Wise 
A1: Month | B1: Portfolios | C1: Impressions | D1: Clicks | E1: CTR | F1: Spend | G1: CPC | H1: Orders | I1: CR | J1: Sales | K1: ACOS | L1: ROAS | M1: Paid AOV | N1: Organic Orders | O1: Organic Sale | P1: Organic AOV | Q1: Total Orders | R1: Total Sale | S1: Total AOV | T1: TACOS | U1: ROI | V1: Sessions | W1: Session % | X1: Organic Orders Cont | Y1: Organic Sales Contribution | Z1: Paid Order Cont | AA1: Paid sales Cont | AB1: Buy Box | AC1: Spend in % | AD1: Paid To Organic Orders
A2: Nov | B2: Sales Day | C2: =SUMIFS('Campaign - Dump'!$N:$N,'Campaign - Dump'!$J:$J,'Portfolio Wise '!$B2,'Campaign - Dump'!$A:$A,'Portfolio Wise '!$A2) -> 4053615 | D2: =SUMIFS('Campaign - Dump'!$O:$O,'Campaign - Dump'!$J:$J,'Portfolio Wise '!$B2,'Campaign - Dump'!$A:$A,'Portfolio Wise '!$A2) -> 12939 | E2: =IFERROR(D2/C2,0) -> 0.0031919657 | F2: =SUMIFS('Campaign - Dump'!$Q:$Q,'Campaign - Dump'!$J:$J,'Portfolio Wise '!$B2,'Campaign - Dump'!$A:$A,'Portfolio Wise '!$A2) -> 162935.35 | G2: =IFERROR(F2/D2,0) -> 12.592577 | H2: =SUMIFS('Campaign - Dump'!$T:$T,'Campaign - Dump'!$J:$J,'Portfolio Wise '!$B2,'Campaign - Dump'!$A:$A,'Portfolio Wise '!$A2) -> 49 | I2: =IFERROR(H2/D2,0) -> 0.0037870005 | J2: =SUMIFS('Campaign - Dump'!$U:$U,'Campaign - Dump'!$J:$J,'Portfolio Wise '!$B2,'Campaign - Dump'!$A:$A,'Portfolio Wise '!$A2) -> 843788.92 | K2: =IFERROR(F2/J2,0) -> 0.19309966 | L2: =IFERROR(J2/F2,0) -> 5.1786731 | M2: =IFERROR(J2/H2,0) -> 17220.182 | N2: 0 | O2: 0 | P2: =IFERROR(O2/N2,0) -> 0 | Q2: =SUMIFS('Business - Dump'!$W:$W,'Business - Dump'!$B:$B,'Portfolio Wise '!$B2,'Business - Dump'!$A:$A,'Portfolio Wise '!$A2) -> 0 | R2: =SUMIFS('Business - Dump'!$U:$U,'Business - Dump'!$B:$B,'Portfolio Wise '!$B2,'Business - Dump'!$A:$A,'Portfolio Wise '!$A2)/1.18 -> 0 | S2: =IFERROR(R2/Q2,0) -> 0 | T2: =IFERROR(F2/R2,0) -> 0 | U2: =IFERROR(R2/F2,0) -> 0 | V2: =SUMIFS('Business - Dump'!$G:$G,'Business - Dump'!$B:$B,'Portfolio Wise '!$B2,'Business - Dump'!$A:$A,'Portfolio Wise '!$A2) -> 0 | W2: =IFERROR(Q2/V2,0) -> 0 | X2: =IFERROR(N2/Q2,0) -> 0 | Y2: =IFERROR(O2/R2,0) -> 0 | Z2: =IFERROR(H2/Q2,0) -> 0 | AA2: =IFERROR(O2/R2,0) -> 0 | AB2: =IFERROR(AVERAGEIFS('Business - Dump'!$O:$O,'Business - Dump'!$B:$B,'Portfolio Wise '!$B2,'Business - Dump'!$A:$A,'Portfolio Wise '!$A2),0) -> 0 | AC2: =F2/SUMIFS('Campaign - Dump'!$Q:$Q,'Campaign - Dump'!$A:$A,'Portfolio Wise '!$A2) -> 0.99914334 | AD2: =IFERROR(N2/H2,0) -> 0
A3: Nov | B3: Standing Table | C3: =SUMIFS('Campaign - Dump'!$N:$N,'Campaign - Dump'!$J:$J,'Portfolio Wise '!$B3,'Campaign - Dump'!$A:$A,'Portfolio Wise '!$A3) -> 0 | D3: =SUMIFS('Campaign - Dump'!$O:$O,'Campaign - Dump'!$J:$J,'Portfolio Wise '!$B3,'Campaign - Dump'!$A:$A,'Portfolio Wise '!$A3) -> 0 | E3: =IFERROR(D3/C3,0) -> 0 | F3: =SUMIFS('Campaign - Dump'!$Q:$Q,'Campaign - Dump'!$J:$J,'Portfolio Wise '!$B3,'Campaign - Dump'!$A:$A,'Portfolio Wise '!$A3) -> 0 | G3: =IFERROR(F3/D3,0) -> 0 | H3: =SUMIFS('Campaign - Dump'!$T:$T,'Campaign - Dump'!$J:$J,'Portfolio Wise '!$B3,'Campaign - Dump'!$A:$A,'Portfolio Wise '!$A3) -> 0 | I3: =IFERROR(H3/D3,0) -> 0 | J3: =SUMIFS('Campaign - Dump'!$U:$U,'Campaign - Dump'!$J:$J,'Portfolio Wise '!$B3,'Campaign - Dump'!$A:$A,'Portfolio Wise '!$A3) -> 0 | K3: =IFERROR(F3/J3,0) -> 0 | L3: =IFERROR(J3/F3,0) -> 0 | M3: =IFERROR(J3/H3,0) -> 0 | N3: =IFERROR(Q3-H3,0) -> 0 | O3: =IFERROR(R3-J3,0) -> 0 | P3: =IFERROR(O3/N3,0) -> 0 | Q3: =SUMIFS('Business - Dump'!$W:$W,'Business - Dump'!$B:$B,'Portfolio Wise '!$B3,'Business - Dump'!$A:$A,'Portfolio Wise '!$A3) -> 0 | R3: =SUMIFS('Business - Dump'!$U:$U,'Business - Dump'!$B:$B,'Portfolio Wise '!$B3,'Business - Dump'!$A:$A,'Portfolio Wise '!$A3)/1.18 -> 0 | S3: =IFERROR(R3/Q3,0) -> 0 | T3: =IFERROR(F3/R3,0) -> 0 | U3: =IFERROR(R3/F3,0) -> 0 | V3: =SUMIFS('Business - Dump'!$G:$G,'Business - Dump'!$B:$B,'Portfolio Wise '!$B3,'Business - Dump'!$A:$A,'Portfolio Wise '!$A3) -> 0 | W3: =IFERROR(Q3/V3,0) -> 0 | X3: =IFERROR(N3/Q3,0) -> 0 | Y3: =IFERROR(O3/R3,0) -> 0 | Z3: =IFERROR(H3/Q3,0) -> 0 | AA3: =IFERROR(O3/R3,0) -> 0 | AB3: =IFERROR(AVERAGEIFS('Business - Dump'!$O:$O,'Business - Dump'!$B:$B,'Portfolio Wise '!$B3,'Business - Dump'!$A:$A,'Portfolio Wise '!$A3),0) -> 0 | AC3: =F3/SUMIFS('Campaign - Dump'!$Q:$Q,'Campaign - Dump'!$A:$A,'Portfolio Wise '!$A3) -> 0 | AD3: =IFERROR(N3/H3,0) -> 0
A4: Nov | B4: TABLE TOP | C4: =SUMIFS('Campaign - Dump'!$N:$N,'Campaign - Dump'!$J:$J,'Portfolio Wise '!$B4,'Campaign - Dump'!$A:$A,'Portfolio Wise '!$A4) -> 1245 | D4: =SUMIFS('Campaign - Dump'!$O:$O,'Campaign - Dump'!$J:$J,'Portfolio Wise '!$B4,'Campaign - Dump'!$A:$A,'Portfolio Wise '!$A4) -> 14 | E4: =IFERROR(D4/C4,0) -> 0.01124498 | F4: =SUMIFS('Campaign - Dump'!$Q:$Q,'Campaign - Dump'!$J:$J,'Portfolio Wise '!$B4,'Campaign - Dump'!$A:$A,'Portfolio Wise '!$A4) -> 88.59 | G4: =IFERROR(F4/D4,0) -> 6.3278571 | H4: =SUMIFS('Campaign - Dump'!$T:$T,'Campaign - Dump'!$J:$J,'Portfolio Wise '!$B4,'Campaign - Dump'!$A:$A,'Portfolio Wise '!$A4) -> 0 | I4: =IFERROR(H4/D4,0) -> 0 | J4: =SUMIFS('Campaign - Dump'!$U:$U,'Campaign - Dump'!$J:$J,'Portfolio Wise '!$B4,'Campaign - Dump'!$A:$A,'Portfolio Wise '!$A4) -> 0 | K4: =IFERROR(F4/J4,0) -> 0 | L4: =IFERROR(J4/F4,0) -> 0 | M4: =IFERROR(J4/H4,0) -> 0 | N4: =IFERROR(Q4-H4,0) -> 2 | O4: =IFERROR(R4-J4,0) -> 10000 | P4: =IFERROR(O4/N4,0) -> 5000 | Q4: =SUMIFS('Business - Dump'!$W:$W,'Business - Dump'!$B:$B,'Portfolio Wise '!$B4,'Business - Dump'!$A:$A,'Portfolio Wise '!$A4) -> 2 | R4: =SUMIFS('Business - Dump'!$U:$U,'Business - Dump'!$B:$B,'Portfolio Wise '!$B4,'Business - Dump'!$A:$A,'Portfolio Wise '!$A4)/1.18 -> 10000 | S4: =IFERROR(R4/Q4,0) -> 5000 | T4: =IFERROR(F4/R4,0) -> 0.008859 | U4: =IFERROR(R4/F4,0) -> 112.87956 | V4: =SUMIFS('Business - Dump'!$G:$G,'Business - Dump'!$B:$B,'Portfolio Wise '!$B4,'Business - Dump'!$A:$A,'Portfolio Wise '!$A4) -> 1637 | W4: =IFERROR(Q4/V4,0) -> 0.0012217471 | X4: =IFERROR(N4/Q4,0) -> 1 | Y4: =IFERROR(O4/R4,0) -> 1 | Z4: =IFERROR(H4/Q4,0) -> 0 | AA4: =IFERROR(O4/R4,0) -> 1 | AB4: =IFERROR(AVERAGEIFS('Business - Dump'!$O:$O,'Business - Dump'!$B:$B,'Portfolio Wise '!$B4,'Business - Dump'!$A:$A,'Portfolio Wise '!$A4),0) -> 0.7159 | AC4: =F4/SUMIFS('Campaign - Dump'!$Q:$Q,'Campaign - Dump'!$A:$A,'Portfolio Wise '!$A4) -> 0.00054324681 | AD4: =IFERROR(N4/H4,0) -> 0
A5: Nov | B5: Brand | C5: =SUMIFS('Campaign - Dump'!$N:$N,'Campaign - Dump'!$J:$J,'Portfolio Wise '!$B5,'Campaign - Dump'!$A:$A,'Portfolio Wise '!$A5) -> 563 | D5: =SUMIFS('Campaign - Dump'!$O:$O,'Campaign - Dump'!$J:$J,'Portfolio Wise '!$B5,'Campaign - Dump'!$A:$A,'Portfolio Wise '!$A5) -> 2 | E5: =IFERROR(D5/C5,0) -> 0.0035523979 | F5: =SUMIFS('Campaign - Dump'!$Q:$Q,'Campaign - Dump'!$J:$J,'Portfolio Wise '!$B5,'Campaign - Dump'!$A:$A,'Portfolio Wise '!$A5) -> 20.01 | G5: =IFERROR(F5/D5,0) -> 10.005 | H5: =SUMIFS('Campaign - Dump'!$T:$T,'Campaign - Dump'!$J:$J,'Portfolio Wise '!$B5,'Campaign - Dump'!$A:$A,'Portfolio Wise '!$A5) -> 0 | I5: =IFERROR(H5/D5,0) -> 0 | J5: =SUMIFS('Campaign - Dump'!$U:$U,'Campaign - Dump'!$J:$J,'Portfolio Wise '!$B5,'Campaign - Dump'!$A:$A,'Portfolio Wise '!$A5) -> 0 | K5: =IFERROR(F5/J5,0) -> 0 | L5: =IFERROR(J5/F5,0) -> 0 | M5: =IFERROR(J5/H5,0) -> 0 | N5: 0 | O5: 0 | P5: =IFERROR(O5/N5,0) -> 0 | Q5: =SUMIFS('Business - Dump'!$W:$W,'Business - Dump'!$B:$B,'Portfolio Wise '!$B5,'Business - Dump'!$A:$A,'Portfolio Wise '!$A5) -> 0 | R5: =SUMIFS('Business - Dump'!$U:$U,'Business - Dump'!$B:$B,'Portfolio Wise '!$B5,'Business - Dump'!$A:$A,'Portfolio Wise '!$A5)/1.18 -> 0 | S5: =IFERROR(R5/Q5,0) -> 0 | T5: =IFERROR(F5/R5,0) -> 0 | U5: =IFERROR(R5/F5,0) -> 0 | V5: =SUMIFS('Business - Dump'!$G:$G,'Business - Dump'!$B:$B,'Portfolio Wise '!$B5,'Business - Dump'!$A:$A,'Portfolio Wise '!$A5) -> 0 | W5: =IFERROR(Q5/V5,0) -> 0 | X5: =IFERROR(N5/Q5,0) -> 0 | Y5: =IFERROR(O5/R5,0) -> 0 | Z5: =IFERROR(H5/Q5,0) -> 0 | AA5: =IFERROR(O5/R5,0) -> 0 | AB5: =IFERROR(AVERAGEIFS('Business - Dump'!$O:$O,'Business - Dump'!$B:$B,'Portfolio Wise '!$B5,'Business - Dump'!$A:$A,'Portfolio Wise '!$A5),0) -> 0 | AC5: =F5/SUMIFS('Campaign - Dump'!$Q:$Q,'Campaign - Dump'!$A:$A,'Portfolio Wise '!$A5) -> 0.00012270424 | AD5: =IFERROR(N5/H5,0) -> 0
A6: Nov | B6: Standing Table - SM3 | C6: =SUMIFS('Campaign - Dump'!$N:$N,'Campaign - Dump'!$J:$J,'Portfolio Wise '!$B6,'Campaign - Dump'!$A:$A,'Portfolio Wise '!$A6) -> 67 | D6: =SUMIFS('Campaign - Dump'!$O:$O,'Campaign - Dump'!$J:$J,'Portfolio Wise '!$B6,'Campaign - Dump'!$A:$A,'Portfolio Wise '!$A6) -> 0 | E6: =IFERROR(D6/C6,0) -> 0 | F6: =SUMIFS('Campaign - Dump'!$Q:$Q,'Campaign - Dump'!$J:$J,'Portfolio Wise '!$B6,'Campaign - Dump'!$A:$A,'Portfolio Wise '!$A6) -> 0 | G6: =IFERROR(F6/D6,0) -> 0 | H6: =SUMIFS('Campaign - Dump'!$T:$T,'Campaign - Dump'!$J:$J,'Portfolio Wise '!$B6,'Campaign - Dump'!$A:$A,'Portfolio Wise '!$A6) -> 0 | I6: =IFERROR(H6/D6,0) -> 0 | J6: =SUMIFS('Campaign - Dump'!$U:$U,'Campaign - Dump'!$J:$J,'Portfolio Wise '!$B6,'Campaign - Dump'!$A:$A,'Portfolio Wise '!$A6) -> 0 | K6: =IFERROR(F6/J6,0) -> 0 | L6: =IFERROR(J6/F6,0) -> 0 | M6: =IFERROR(J6/H6,0) -> 0 | N6: =IFERROR(Q6-H6,0) -> 34 | O6: =IFERROR(R6-J6,0) -> 654067.8 | P6: =IFERROR(O6/N6,0) -> 19237.288 | Q6: =SUMIFS('Business - Dump'!$W:$W,'Business - Dump'!$B:$B,'Portfolio Wise '!$B6,'Business - Dump'!$A:$A,'Portfolio Wise '!$A6) -> 34 | R6: =SUMIFS('Business - Dump'!$U:$U,'Business - Dump'!$B:$B,'Portfolio Wise '!$B6,'Business - Dump'!$A:$A,'Portfolio Wise '!$A6)/1.18 -> 654067.8 | S6: =IFERROR(R6/Q6,0) -> 19237.288 | T6: =IFERROR(F6/R6,0) -> 0 | U6: =IFERROR(R6/F6,0) -> 0 | V6: =SUMIFS('Business - Dump'!$G:$G,'Business - Dump'!$B:$B,'Portfolio Wise '!$B6,'Business - Dump'!$A:$A,'Portfolio Wise '!$A6) -> 7626 | W6: =IFERROR(Q6/V6,0) -> 0.0044584317 | X6: =IFERROR(N6/Q6,0) -> 1 | Y6: =IFERROR(O6/R6,0) -> 1 | Z6: =IFERROR(H6/Q6,0) -> 0 | AA6: =IFERROR(O6/R6,0) -> 1 | AB6: =IFERROR(AVERAGEIFS('Business - Dump'!$O:$O,'Business - Dump'!$B:$B,'Portfolio Wise '!$B6,'Business - Dump'!$A:$A,'Portfolio Wise '!$A6),0) -> 0.925275 | AC6: =F6/SUMIFS('Campaign - Dump'!$Q:$Q,'Campaign - Dump'!$A:$A,'Portfolio Wise '!$A6) -> 0 | AD6: =IFERROR(N6/H6,0) -> 0
A7: Nov | B7: Standing Table - E2 | C7: =SUMIFS('Campaign - Dump'!$N:$N,'Campaign - Dump'!$J:$J,'Portfolio Wise '!$B7,'Campaign - Dump'!$A:$A,'Portfolio Wise '!$A7) -> 729 | D7: =SUMIFS('Campaign - Dump'!$O:$O,'Campaign - Dump'!$J:$J,'Portfolio Wise '!$B7,'Campaign - Dump'!$A:$A,'Portfolio Wise '!$A7) -> 4 | E7: =IFERROR(D7/C7,0) -> 0.0054869684 | F7: =SUMIFS('Campaign - Dump'!$Q:$Q,'Campaign - Dump'!$J:$J,'Portfolio Wise '!$B7,'Campaign - Dump'!$A:$A,'Portfolio Wise '!$A7) -> 31.1 | G7: =IFERROR(F7/D7,0) -> 7.775 | H7: =SUMIFS('Campaign - Dump'!$T:$T,'Campaign - Dump'!$J:$J,'Portfolio Wise '!$B7,'Campaign - Dump'!$A:$A,'Portfolio Wise '!$A7) -> 0 | I7: =IFERROR(H7/D7,0) -> 0 | J7: =SUMIFS('Campaign - Dump'!$U:$U,'Campaign - Dump'!$J:$J,'Portfolio Wise '!$B7,'Campaign - Dump'!$A:$A,'Portfolio Wise '!$A7) -> 0 | K7: =IFERROR(F7/J7,0) -> 0 | L7: =IFERROR(J7/F7,0) -> 0 | M7: =IFERROR(J7/H7,0) -> 0 | N7: =IFERROR(Q7-H7,0) -> 20 | O7: =IFERROR(R7-J7,0) -> 536745.76 | P7: =IFERROR(O7/N7,0) -> 26837.288 | Q7: =SUMIFS('Business - Dump'!$W:$W,'Business - Dump'!$B:$B,'Portfolio Wise '!$B7,'Business - Dump'!$A:$A,'Portfolio Wise '!$A7) -> 20 | R7: =SUMIFS('Business - Dump'!$U:$U,'Business - Dump'!$B:$B,'Portfolio Wise '!$B7,'Business - Dump'!$A:$A,'Portfolio Wise '!$A7)/1.18 -> 536745.76 | S7: =IFERROR(R7/Q7,0) -> 26837.288 | T7: =IFERROR(F7/R7,0) -> 5.7941771e-05 | U7: =IFERROR(R7/F7,0) -> 17258.706 | V7: =SUMIFS('Business - Dump'!$G:$G,'Business - Dump'!$B:$B,'Portfolio Wise '!$B7,'Business - Dump'!$A:$A,'Portfolio Wise '!$A7) -> 3887 | W7: =IFERROR(Q7/V7,0) -> 0.0051453563 | X7: =IFERROR(N7/Q7,0) -> 1 | Y7: =IFERROR(O7/R7,0) -> 1 | Z7: =IFERROR(H7/Q7,0) -> 0 | AA7: =IFERROR(O7/R7,0) -> 1 | AB7: =IFERROR(AVERAGEIFS('Business - Dump'!$O:$O,'Business - Dump'!$B:$B,'Portfolio Wise '!$B7,'Business - Dump'!$A:$A,'Portfolio Wise '!$A7),0) -> 0.83335 | AC7: =F7/SUMIFS('Campaign - Dump'!$Q:$Q,'Campaign - Dump'!$A:$A,'Portfolio Wise '!$A7) -> 0.00019070974 | AD7: =IFERROR(N7/H7,0) -> 0
A8: Nov | B8: Standing Table - M3 | C8: =SUMIFS('Campaign - Dump'!$N:$N,'Campaign - Dump'!$J:$J,'Portfolio Wise '!$B8,'Campaign - Dump'!$A:$A,'Portfolio Wise '!$A8) -> 0 | D8: =SUMIFS('Campaign - Dump'!$O:$O,'Campaign - Dump'!$J:$J,'Portfolio Wise '!$B8,'Campaign - Dump'!$A:$A,'Portfolio Wise '!$A8) -> 0 | E8: =IFERROR(D8/C8,0) -> 0 | F8: =SUMIFS('Campaign - Dump'!$Q:$Q,'Campaign - Dump'!$J:$J,'Portfolio Wise '!$B8,'Campaign - Dump'!$A:$A,'Portfolio Wise '!$A8) -> 0 | G8: =IFERROR(F8/D8,0) -> 0 | H8: =SUMIFS('Campaign - Dump'!$T:$T,'Campaign - Dump'!$J:$J,'Portfolio Wise '!$B8,'Campaign - Dump'!$A:$A,'Portfolio Wise '!$A8) -> 0 | I8: =IFERROR(H8/D8,0) -> 0 | J8: =SUMIFS('Campaign - Dump'!$U:$U,'Campaign - Dump'!$J:$J,'Portfolio Wise '!$B8,'Campaign - Dump'!$A:$A,'Portfolio Wise '!$A8) -> 0 | K8: =IFERROR(F8/J8,0) -> 0 | L8: =IFERROR(J8/F8,0) -> 0 | M8: =IFERROR(J8/H8,0) -> 0 | N8: =IFERROR(Q8-H8,0) -> 0 | O8: =IFERROR(R8-J8,0) -> 0 | P8: =IFERROR(O8/N8,0) -> 0 | Q8: =SUMIFS('Business - Dump'!$W:$W,'Business - Dump'!$B:$B,'Portfolio Wise '!$B8,'Business - Dump'!$A:$A,'Portfolio Wise '!$A8) -> 0 | R8: =SUMIFS('Business - Dump'!$U:$U,'Business - Dump'!$B:$B,'Portfolio Wise '!$B8,'Business - Dump'!$A:$A,'Portfolio Wise '!$A8)/1.18 -> 0 | S8: =IFERROR(R8/Q8,0) -> 0 | T8: =IFERROR(F8/R8,0) -> 0 | U8: =IFERROR(R8/F8,0) -> 0 | V8: =SUMIFS('Business - Dump'!$G:$G,'Business - Dump'!$B:$B,'Portfolio Wise '!$B8,'Business - Dump'!$A:$A,'Portfolio Wise '!$A8) -> 0 | W8: =IFERROR(Q8/V8,0) -> 0 | X8: =IFERROR(N8/Q8,0) -> 0 | Y8: =IFERROR(O8/R8,0) -> 0 | Z8: =IFERROR(H8/Q8,0) -> 0 | AA8: =IFERROR(O8/R8,0) -> 0 | AB8: =IFERROR(AVERAGEIFS('Business - Dump'!$O:$O,'Business - Dump'!$B:$B,'Portfolio Wise '!$B8,'Business - Dump'!$A:$A,'Portfolio Wise '!$A8),0) -> 0 | AC8: =F8/SUMIFS('Campaign - Dump'!$Q:$Q,'Campaign - Dump'!$A:$A,'Portfolio Wise '!$A8) -> 0 | AD8: =IFERROR(N8/H8,0) -> 0
